Failure # 1 (occurred at 2020-09-10_19-34-16)
Traceback (most recent call last):
  File "/home/fadil/anaconda3/envs/ML2/lib/python3.7/site-packages/ray/tune/trial_runner.py", line 471, in _process_trial
    result = self.trial_executor.fetch_result(trial)
  File "/home/fadil/anaconda3/envs/ML2/lib/python3.7/site-packages/ray/tune/ray_trial_executor.py", line 430, in fetch_result
    result = ray.get(trial_future[0], DEFAULT_GET_TIMEOUT)
  File "/home/fadil/anaconda3/envs/ML2/lib/python3.7/site-packages/ray/worker.py", line 1538, in get
    raise value.as_instanceof_cause()
ray.exceptions.RayTaskError: [36mray::WrappedTrainable.train()[39m (pid=7413, ip=192.168.0.199)
  File "python/ray/_raylet.pyx", line 432, in ray._raylet.execute_task.function_executor
  File "/home/fadil/anaconda3/envs/ML2/lib/python3.7/site-packages/ray/tune/trainable.py", line 332, in train
    result = self.step()
  File "/home/fadil/anaconda3/envs/ML2/lib/python3.7/site-packages/ray/tune/trainable.py", line 636, in step
    result = self._train()
  File "random_forest_hpo.py", line 121, in _train
    trained_model = self.rf_model.fit(X_train, y_train.astype("float32"))
KeyboardInterrupt

During handling of the above exception, another exception occurred:

[36mray::WrappedTrainable.train()[39m (pid=7413, ip=192.168.0.199)
  File "python/ray/_raylet.pyx", line 474, in ray._raylet.execute_task
  File "python/ray/_raylet.pyx", line 482, in ray._raylet.execute_task
ray.exceptions.RayCancellationError: Task: TaskID(ffffffffffffffffffffffff0100) was cancelled

